ERROR:app:Exception on /medico/dashboard [GET]
Traceback (most recent call last):
  File "/home/runner/workspace/.pythonlibs/lib/python3.11/site-packages/flask/app.py", line 1511, in wsgi_app
    response = self.full_dispatch_request()
               ^^^^^^^^^^^^^^^^^^^^^^^^^^^^
  File "/home/runner/workspace/.pythonlibs/lib/python3.11/site-packages/flask/app.py", line 919, in full_dispatch_request
    rv = self.handle_user_exception(e)
         ^^^^^^^^^^^^^^^^^^^^^^^^^^^^^
  File "/home/runner/workspace/.pythonlibs/lib/python3.11/site-packages/flask/app.py", line 917, in full_dispatch_request
    rv = self.dispatch_request()
         ^^^^^^^^^^^^^^^^^^^^^^^
  File "/home/runner/workspace/.pythonlibs/lib/python3.11/site-packages/flask/app.py", line 902, in dispatch_request
    return self.ensure_sync(self.view_functions[rule.endpoint])(**view_args)  # type: ignore[no-any-return]
           ^^^^^^^^^^^^^^^^^^^^^^^^^^^^^^^^^^^^^^^^^^^^^^^^^^^^^^^^^^^^^^^^^
  File "/home/runner/workspace/app.py", line 266, in medico_dashboard
    return render_template('medico_dashboard.html',
          ^^^^^^^^^^^^^^^^^^^^^^^^^^^^^^^^^^^^^^^^
  File "/home/runner/workspace/.pythonlibs/lib/python3.11/site-packages/flask/templating.py", line 150, in render_template
    return _render(app, template, context)
           ^^^^^^^^^^^^^^^^^^^^^^^^^^^^^^^
  File "/home/runner/workspace/.pythonlibs/lib/python3.11/site-packages/flask/templating.py", line 131, in _render
    rv = template.render(context)
         ^^^^^^^^^^^^^^^^^^^^^^^^
  File "/home/runner/workspace/.pythonlibs/lib/python3.11/site-packages/jinja2/environment.py", line 1295, in render
    self.environment.handle_exception()
  File "/home/runner/workspace/.pythonlibs/lib/python3.11/site-packages/jinja2/environment.py", line 942, in handle_exception
    raise rewrite_traceback_stack(source=source)
  File "/home/runner/workspace/templates/medico_dashboard.html", line 186, in top-level template code
    {{ paciente.nome[0].upper() }}
    ^^^^^^^^^^^^^^^^^^^^^^^^^
  File "/home/runner/workspace/.pythonlibs/lib/python3.11/site-packages/jinja2/environment.py", line 471, in getitem
    return obj[argument]
           ~~~^^^^^^^^^^
jinja2.exceptions.UndefinedError: 'tuple object' has no attribute 'nome'